2018-11-29 03:13:17,126 INFO: Microblog startup [in D:\flask_microblog\flask_microblog\app\__init__.py:57]
2018-11-29 03:53:25,653 INFO: Microblog startup [in D:\flask_microblog\flask_microblog\app\__init__.py:57]
2018-11-29 04:05:33,345 INFO: Microblog startup [in D:\flask_microblog\flask_microblog\app\__init__.py:57]
2018-11-29 04:12:01,274 ERROR: Exception on /user/emc [GET] [in c:\program files\python3\lib\site-packages\flask\app.py:1761]
Traceback (most recent call last):
  File "c:\program files\python3\lib\site-packages\flask\app.py", line 2292, in wsgi_app
    response = self.full_dispatch_request()
  File "c:\program files\python3\lib\site-packages\flask\app.py", line 1815, in full_dispatch_request
    rv = self.handle_user_exception(e)
  File "c:\program files\python3\lib\site-packages\flask\app.py", line 1718, in handle_user_exception
    reraise(exc_type, exc_value, tb)
  File "c:\program files\python3\lib\site-packages\flask\_compat.py", line 35, in reraise
    raise value
  File "c:\program files\python3\lib\site-packages\flask\app.py", line 1813, in full_dispatch_request
    rv = self.dispatch_request()
  File "c:\program files\python3\lib\site-packages\flask\app.py", line 1799, in dispatch_request
    return self.view_functions[rule.endpoint](**req.view_args)
  File "c:\program files\python3\lib\site-packages\flask_login\utils.py", line 261, in decorated_view
    return func(*args, **kwargs)
  File "D:\flask_microblog\flask_microblog\app\routes.py", line 86, in user
    return render_template('user.html', user=user, posts=posts)
  File "c:\program files\python3\lib\site-packages\flask\templating.py", line 135, in render_template
    context, ctx.app)
  File "c:\program files\python3\lib\site-packages\flask\templating.py", line 117, in _render
    rv = template.render(context)
  File "c:\program files\python3\lib\site-packages\jinja2\asyncsupport.py", line 76, in render
    return original_render(self, *args, **kwargs)
  File "c:\program files\python3\lib\site-packages\jinja2\environment.py", line 1008, in render
    return self.environment.handle_exception(exc_info, True)
  File "c:\program files\python3\lib\site-packages\jinja2\environment.py", line 780, in handle_exception
    reraise(exc_type, exc_value, tb)
  File "c:\program files\python3\lib\site-packages\jinja2\_compat.py", line 37, in reraise
    raise value.with_traceback(tb)
  File "D:\flask_microblog\flask_microblog\app\templates\user.html", line 1, in top-level template code
    {% extends "base.html" %}
  File "D:\flask_microblog\flask_microblog\app\templates\base.html", line 29, in top-level template code
    {% block content %} {% endblock %}
  File "D:\flask_microblog\flask_microblog\app\templates\user.html", line 15, in block "content"
    <p><a href="{{ url_for('follow', username=user.username) }}">Follow</a></p>
  File "c:\program files\python3\lib\site-packages\flask\helpers.py", line 356, in url_for
    return appctx.app.handle_url_build_error(error, endpoint, values)
  File "c:\program files\python3\lib\site-packages\flask\app.py", line 2061, in handle_url_build_error
    reraise(exc_type, exc_value, tb)
  File "c:\program files\python3\lib\site-packages\flask\_compat.py", line 35, in reraise
    raise value
  File "c:\program files\python3\lib\site-packages\flask\helpers.py", line 345, in url_for
    force_external=external)
  File "c:\program files\python3\lib\site-packages\werkzeug\routing.py", line 1776, in build
    raise BuildError(endpoint, values, method, self)
werkzeug.routing.BuildError: Could not build url for endpoint 'follow' with values ['username']. Did you mean 'login' instead?
2018-11-29 04:12:14,803 ERROR: Exception on /user/steph [GET] [in c:\program files\python3\lib\site-packages\flask\app.py:1761]
Traceback (most recent call last):
  File "c:\program files\python3\lib\site-packages\flask\app.py", line 2292, in wsgi_app
    response = self.full_dispatch_request()
  File "c:\program files\python3\lib\site-packages\flask\app.py", line 1815, in full_dispatch_request
    rv = self.handle_user_exception(e)
  File "c:\program files\python3\lib\site-packages\flask\app.py", line 1718, in handle_user_exception
    reraise(exc_type, exc_value, tb)
  File "c:\program files\python3\lib\site-packages\flask\_compat.py", line 35, in reraise
    raise value
  File "c:\program files\python3\lib\site-packages\flask\app.py", line 1813, in full_dispatch_request
    rv = self.dispatch_request()
  File "c:\program files\python3\lib\site-packages\flask\app.py", line 1799, in dispatch_request
    return self.view_functions[rule.endpoint](**req.view_args)
  File "c:\program files\python3\lib\site-packages\flask_login\utils.py", line 261, in decorated_view
    return func(*args, **kwargs)
  File "D:\flask_microblog\flask_microblog\app\routes.py", line 86, in user
    return render_template('user.html', user=user, posts=posts)
  File "c:\program files\python3\lib\site-packages\flask\templating.py", line 135, in render_template
    context, ctx.app)
  File "c:\program files\python3\lib\site-packages\flask\templating.py", line 117, in _render
    rv = template.render(context)
  File "c:\program files\python3\lib\site-packages\jinja2\asyncsupport.py", line 76, in render
    return original_render(self, *args, **kwargs)
  File "c:\program files\python3\lib\site-packages\jinja2\environment.py", line 1008, in render
    return self.environment.handle_exception(exc_info, True)
  File "c:\program files\python3\lib\site-packages\jinja2\environment.py", line 780, in handle_exception
    reraise(exc_type, exc_value, tb)
  File "c:\program files\python3\lib\site-packages\jinja2\_compat.py", line 37, in reraise
    raise value.with_traceback(tb)
  File "D:\flask_microblog\flask_microblog\app\templates\user.html", line 1, in top-level template code
    {% extends "base.html" %}
  File "D:\flask_microblog\flask_microblog\app\templates\base.html", line 29, in top-level template code
    {% block content %} {% endblock %}
  File "D:\flask_microblog\flask_microblog\app\templates\user.html", line 15, in block "content"
    <p><a href="{{ url_for('follow', username=user.username) }}">Follow</a></p>
  File "c:\program files\python3\lib\site-packages\flask\helpers.py", line 356, in url_for
    return appctx.app.handle_url_build_error(error, endpoint, values)
  File "c:\program files\python3\lib\site-packages\flask\app.py", line 2061, in handle_url_build_error
    reraise(exc_type, exc_value, tb)
  File "c:\program files\python3\lib\site-packages\flask\_compat.py", line 35, in reraise
    raise value
  File "c:\program files\python3\lib\site-packages\flask\helpers.py", line 345, in url_for
    force_external=external)
  File "c:\program files\python3\lib\site-packages\werkzeug\routing.py", line 1776, in build
    raise BuildError(endpoint, values, method, self)
werkzeug.routing.BuildError: Could not build url for endpoint 'follow' with values ['username']. Did you mean 'login' instead?
